2025-07-27 06:13:46 - INFO - __main__ - Initializing Streamlit dashboard
2025-07-27 06:13:46 - INFO - __main__ - Initializing Streamlit dashboard
2025-07-27 06:13:46 - ERROR - utils - File not found: data/aws_hybrid_usage.csv
2025-07-27 06:13:46 - ERROR - utils - File not found: data/aws_hybrid_usage.csv
2025-07-27 06:13:46 - ERROR - utils - Error loading data/aws_hybrid_usage.csv: Data file data/aws_hybrid_usage.csv does not exist
Traceback (most recent call last):
  File "C:\Users\Asus-PC\cloud-saver\streamlit\utils.py", line 13, in load_data
    raise FileNotFoundError(f"Data file {file_path} does not exist")
FileNotFoundError: Data file data/aws_hybrid_usage.csv does not exist
2025-07-27 06:13:46 - ERROR - utils - Error loading data/aws_hybrid_usage.csv: Data file data/aws_hybrid_usage.csv does not exist
Traceback (most recent call last):
  File "C:\Users\Asus-PC\cloud-saver\streamlit\utils.py", line 13, in load_data
    raise FileNotFoundError(f"Data file {file_path} does not exist")
FileNotFoundError: Data file data/aws_hybrid_usage.csv does not exist
2025-07-27 06:13:46 - ERROR - __main__ - Dashboard error: Data file data/aws_hybrid_usage.csv does not exist
Traceback (most recent call last):
  File "C:\Users\Asus-PC\cloud-saver\streamlit\app.py", line 32, in main
    cost_data = load_data("data/aws_hybrid_usage.csv")
                ^^^^^^^^^^^^^^^^^^^^^^^^^^^^^^^^^^^^^^
  File "C:\Users\Asus-PC\cloud-saver\streamlit\utils.py", line 13, in load_data
    raise FileNotFoundError(f"Data file {file_path} does not exist")
FileNotFoundError: Data file data/aws_hybrid_usage.csv does not exist
2025-07-27 06:13:46 - ERROR - __main__ - Dashboard error: Data file data/aws_hybrid_usage.csv does not exist
Traceback (most recent call last):
  File "C:\Users\Asus-PC\cloud-saver\streamlit\app.py", line 32, in main
    cost_data = load_data("data/aws_hybrid_usage.csv")
                ^^^^^^^^^^^^^^^^^^^^^^^^^^^^^^^^^^^^^^
  File "C:\Users\Asus-PC\cloud-saver\streamlit\utils.py", line 13, in load_data
    raise FileNotFoundError(f"Data file {file_path} does not exist")
FileNotFoundError: Data file data/aws_hybrid_usage.csv does not exist
2025-07-27 06:13:48 - INFO - __main__ - Initializing Streamlit dashboard
2025-07-27 06:13:48 - ERROR - utils - File not found: data/aws_hybrid_usage.csv
2025-07-27 06:13:48 - ERROR - utils - Error loading data/aws_hybrid_usage.csv: Data file data/aws_hybrid_usage.csv does not exist
Traceback (most recent call last):
  File "C:\Users\Asus-PC\cloud-saver\streamlit\utils.py", line 13, in load_data
    raise FileNotFoundError(f"Data file {file_path} does not exist")
FileNotFoundError: Data file data/aws_hybrid_usage.csv does not exist
2025-07-27 06:13:48 - ERROR - __main__ - Dashboard error: Data file data/aws_hybrid_usage.csv does not exist
Traceback (most recent call last):
  File "C:\Users\Asus-PC\cloud-saver\streamlit\app.py", line 32, in main
    cost_data = load_data("data/aws_hybrid_usage.csv")
                ^^^^^^^^^^^^^^^^^^^^^^^^^^^^^^^^^^^^^^
  File "C:\Users\Asus-PC\cloud-saver\streamlit\utils.py", line 13, in load_data
    raise FileNotFoundError(f"Data file {file_path} does not exist")
FileNotFoundError: Data file data/aws_hybrid_usage.csv does not exist
2025-07-27 06:38:32 - INFO - __main__ - Initializing Streamlit dashboard
2025-07-27 06:38:32 - ERROR - utils - File not found: data/aws_hybrid_usage.csv
2025-07-27 06:38:32 - ERROR - utils - Error loading data/aws_hybrid_usage.csv: Data file data/aws_hybrid_usage.csv does not exist
Traceback (most recent call last):
  File "C:\Users\Asus-PC\cloud-saver\streamlit\utils.py", line 13, in load_data
    raise FileNotFoundError(f"Data file {file_path} does not exist")
FileNotFoundError: Data file data/aws_hybrid_usage.csv does not exist
2025-07-27 06:38:32 - ERROR - __main__ - Dashboard error: Data file data/aws_hybrid_usage.csv does not exist
Traceback (most recent call last):
  File "C:\Users\Asus-PC\cloud-saver\streamlit\app.py", line 32, in main
    cost_data = load_data("data/aws_hybrid_usage.csv")
                ^^^^^^^^^^^^^^^^^^^^^^^^^^^^^^^^^^^^^^
  File "C:\Users\Asus-PC\cloud-saver\streamlit\utils.py", line 13, in load_data
    raise FileNotFoundError(f"Data file {file_path} does not exist")
FileNotFoundError: Data file data/aws_hybrid_usage.csv does not exist
2025-07-27 06:48:50 - INFO - __main__ - Initializing Streamlit dashboard
2025-07-27 06:48:50 - INFO - __main__ - Initializing Streamlit dashboard
2025-07-27 06:48:50 - ERROR - utils - File not found: C:\Users\Asus-PC\cloud-saver\streamlit\data\aws_hybrid_usage.csv
Directory contents: []
2025-07-27 06:48:50 - ERROR - utils - Failed to load aws_hybrid_usage.csv: FileNotFoundError
Error: Data file not found at: C:\Users\Asus-PC\cloud-saver\streamlit\data\aws_hybrid_usage.csv
Available files: []
File size: 0 bytes
Traceback (most recent call last):
  File "C:\Users\Asus-PC\cloud-saver\streamlit\utils.py", line 36, in load_data
    raise FileNotFoundError(
FileNotFoundError: Data file not found at: C:\Users\Asus-PC\cloud-saver\streamlit\data\aws_hybrid_usage.csv
Available files: []
2025-07-27 06:48:50 - CRITICAL - __main__ - Data file missing: Data file not found at: C:\Users\Asus-PC\cloud-saver\streamlit\data\aws_hybrid_usage.csv
Available files: []
Traceback (most recent call last):
  File "C:\Users\Asus-PC\cloud-saver\streamlit\app.py", line 44, in main
    cost_data = load_data(cost_data_path)
                ^^^^^^^^^^^^^^^^^^^^^^^^^
  File "C:\Users\Asus-PC\cloud-saver\streamlit\utils.py", line 36, in load_data
    raise FileNotFoundError(
FileNotFoundError: Data file not found at: C:\Users\Asus-PC\cloud-saver\streamlit\data\aws_hybrid_usage.csv
Available files: []
2025-07-27 06:48:51 - ERROR - utils - File not found: C:\Users\Asus-PC\cloud-saver\streamlit\data\aws_hybrid_usage.csv
Directory contents: []
2025-07-27 06:48:51 - ERROR - utils - Failed to load aws_hybrid_usage.csv: FileNotFoundError
Error: Data file not found at: C:\Users\Asus-PC\cloud-saver\streamlit\data\aws_hybrid_usage.csv
Available files: []
File size: 0 bytes
Traceback (most recent call last):
  File "C:\Users\Asus-PC\cloud-saver\streamlit\utils.py", line 36, in load_data
    raise FileNotFoundError(
FileNotFoundError: Data file not found at: C:\Users\Asus-PC\cloud-saver\streamlit\data\aws_hybrid_usage.csv
Available files: []
2025-07-27 06:48:51 - CRITICAL - __main__ - Data file missing: Data file not found at: C:\Users\Asus-PC\cloud-saver\streamlit\data\aws_hybrid_usage.csv
Available files: []
Traceback (most recent call last):
  File "C:\Users\Asus-PC\cloud-saver\streamlit\app.py", line 44, in main
    cost_data = load_data(cost_data_path)
                ^^^^^^^^^^^^^^^^^^^^^^^^^
  File "C:\Users\Asus-PC\cloud-saver\streamlit\utils.py", line 36, in load_data
    raise FileNotFoundError(
FileNotFoundError: Data file not found at: C:\Users\Asus-PC\cloud-saver\streamlit\data\aws_hybrid_usage.csv
Available files: []
2025-07-27 06:54:35 - INFO - __main__ - Initializing Streamlit dashboard
2025-07-27 06:54:35 - INFO - __main__ - Initializing Streamlit dashboard
2025-07-27 06:54:35 - ERROR - utils - Failed to load aws_hybrid_usage.csv: ValueError
Error: Missing column provided to 'parse_dates': 'date'
File size: 3019 bytes
Traceback (most recent call last):
  File "C:\Users\Asus-PC\cloud-saver\streamlit\utils.py", line 42, in load_data
    df = pd.read_csv(
         ^^^^^^^^^^^^
  File "C:\Users\Asus-PC\AppData\Local\Programs\Python\Python311\Lib\site-packages\pandas\io\parsers\readers.py", line 1026, in read_csv
    return _read(filepath_or_buffer, kwds)
           ^^^^^^^^^^^^^^^^^^^^^^^^^^^^^^^
  File "C:\Users\Asus-PC\AppData\Local\Programs\Python\Python311\Lib\site-packages\pandas\io\parsers\readers.py", line 620, in _read
    parser = TextFileReader(filepath_or_buffer, **kwds)
             ^^^^^^^^^^^^^^^^^^^^^^^^^^^^^^^^^^^^^^^^^^
  File "C:\Users\Asus-PC\AppData\Local\Programs\Python\Python311\Lib\site-packages\pandas\io\parsers\readers.py", line 1620, in __init__
    self._engine = self._make_engine(f, self.engine)
                   ^^^^^^^^^^^^^^^^^^^^^^^^^^^^^^^^^
  File "C:\Users\Asus-PC\AppData\Local\Programs\Python\Python311\Lib\site-packages\pandas\io\parsers\readers.py", line 1898, in _make_engine
    return mapping[engine](f, **self.options)
           ^^^^^^^^^^^^^^^^^^^^^^^^^^^^^^^^^^
  File "C:\Users\Asus-PC\AppData\Local\Programs\Python\Python311\Lib\site-packages\pandas\io\parsers\c_parser_wrapper.py", line 161, in __init__
    self._validate_parse_dates_presence(self.names)  # type: ignore[has-type]
    ^^^^^^^^^^^^^^^^^^^^^^^^^^^^^^^^^^^^^^^^^^^^^^^
  File "C:\Users\Asus-PC\AppData\Local\Programs\Python\Python311\Lib\site-packages\pandas\io\parsers\base_parser.py", line 243, in _validate_parse_dates_presence
    raise ValueError(
ValueError: Missing column provided to 'parse_dates': 'date'
2025-07-27 06:54:35 - CRITICAL - __main__ - Critical dashboard error: Missing column provided to 'parse_dates': 'date'
Traceback (most recent call last):
  File "C:\Users\Asus-PC\cloud-saver\streamlit\app.py", line 80, in main
    cost_data = load_data(cost_data_path)
                ^^^^^^^^^^^^^^^^^^^^^^^^^
  File "C:\Users\Asus-PC\cloud-saver\streamlit\utils.py", line 42, in load_data
    df = pd.read_csv(
         ^^^^^^^^^^^^
  File "C:\Users\Asus-PC\AppData\Local\Programs\Python\Python311\Lib\site-packages\pandas\io\parsers\readers.py", line 1026, in read_csv
    return _read(filepath_or_buffer, kwds)
           ^^^^^^^^^^^^^^^^^^^^^^^^^^^^^^^
  File "C:\Users\Asus-PC\AppData\Local\Programs\Python\Python311\Lib\site-packages\pandas\io\parsers\readers.py", line 620, in _read
    parser = TextFileReader(filepath_or_buffer, **kwds)
             ^^^^^^^^^^^^^^^^^^^^^^^^^^^^^^^^^^^^^^^^^^
  File "C:\Users\Asus-PC\AppData\Local\Programs\Python\Python311\Lib\site-packages\pandas\io\parsers\readers.py", line 1620, in __init__
    self._engine = self._make_engine(f, self.engine)
                   ^^^^^^^^^^^^^^^^^^^^^^^^^^^^^^^^^
  File "C:\Users\Asus-PC\AppData\Local\Programs\Python\Python311\Lib\site-packages\pandas\io\parsers\readers.py", line 1898, in _make_engine
    return mapping[engine](f, **self.options)
           ^^^^^^^^^^^^^^^^^^^^^^^^^^^^^^^^^^
  File "C:\Users\Asus-PC\AppData\Local\Programs\Python\Python311\Lib\site-packages\pandas\io\parsers\c_parser_wrapper.py", line 161, in __init__
    self._validate_parse_dates_presence(self.names)  # type: ignore[has-type]
    ^^^^^^^^^^^^^^^^^^^^^^^^^^^^^^^^^^^^^^^^^^^^^^^
  File "C:\Users\Asus-PC\AppData\Local\Programs\Python\Python311\Lib\site-packages\pandas\io\parsers\base_parser.py", line 243, in _validate_parse_dates_presence
    raise ValueError(
ValueError: Missing column provided to 'parse_dates': 'date'
2025-07-27 06:54:35 - ERROR - utils - Failed to load aws_hybrid_usage.csv: ValueError
Error: Missing column provided to 'parse_dates': 'date'
File size: 3019 bytes
Traceback (most recent call last):
  File "C:\Users\Asus-PC\cloud-saver\streamlit\utils.py", line 42, in load_data
    df = pd.read_csv(
         ^^^^^^^^^^^^
  File "C:\Users\Asus-PC\AppData\Local\Programs\Python\Python311\Lib\site-packages\pandas\io\parsers\readers.py", line 1026, in read_csv
    return _read(filepath_or_buffer, kwds)
           ^^^^^^^^^^^^^^^^^^^^^^^^^^^^^^^
  File "C:\Users\Asus-PC\AppData\Local\Programs\Python\Python311\Lib\site-packages\pandas\io\parsers\readers.py", line 620, in _read
    parser = TextFileReader(filepath_or_buffer, **kwds)
             ^^^^^^^^^^^^^^^^^^^^^^^^^^^^^^^^^^^^^^^^^^
  File "C:\Users\Asus-PC\AppData\Local\Programs\Python\Python311\Lib\site-packages\pandas\io\parsers\readers.py", line 1620, in __init__
    self._engine = self._make_engine(f, self.engine)
                   ^^^^^^^^^^^^^^^^^^^^^^^^^^^^^^^^^
  File "C:\Users\Asus-PC\AppData\Local\Programs\Python\Python311\Lib\site-packages\pandas\io\parsers\readers.py", line 1898, in _make_engine
    return mapping[engine](f, **self.options)
           ^^^^^^^^^^^^^^^^^^^^^^^^^^^^^^^^^^
  File "C:\Users\Asus-PC\AppData\Local\Programs\Python\Python311\Lib\site-packages\pandas\io\parsers\c_parser_wrapper.py", line 161, in __init__
    self._validate_parse_dates_presence(self.names)  # type: ignore[has-type]
    ^^^^^^^^^^^^^^^^^^^^^^^^^^^^^^^^^^^^^^^^^^^^^^^
  File "C:\Users\Asus-PC\AppData\Local\Programs\Python\Python311\Lib\site-packages\pandas\io\parsers\base_parser.py", line 243, in _validate_parse_dates_presence
    raise ValueError(
ValueError: Missing column provided to 'parse_dates': 'date'
2025-07-27 06:54:35 - CRITICAL - __main__ - Critical dashboard error: Missing column provided to 'parse_dates': 'date'
Traceback (most recent call last):
  File "C:\Users\Asus-PC\cloud-saver\streamlit\app.py", line 80, in main
    cost_data = load_data(cost_data_path)
                ^^^^^^^^^^^^^^^^^^^^^^^^^
  File "C:\Users\Asus-PC\cloud-saver\streamlit\utils.py", line 42, in load_data
    df = pd.read_csv(
         ^^^^^^^^^^^^
  File "C:\Users\Asus-PC\AppData\Local\Programs\Python\Python311\Lib\site-packages\pandas\io\parsers\readers.py", line 1026, in read_csv
    return _read(filepath_or_buffer, kwds)
           ^^^^^^^^^^^^^^^^^^^^^^^^^^^^^^^
  File "C:\Users\Asus-PC\AppData\Local\Programs\Python\Python311\Lib\site-packages\pandas\io\parsers\readers.py", line 620, in _read
    parser = TextFileReader(filepath_or_buffer, **kwds)
             ^^^^^^^^^^^^^^^^^^^^^^^^^^^^^^^^^^^^^^^^^^
  File "C:\Users\Asus-PC\AppData\Local\Programs\Python\Python311\Lib\site-packages\pandas\io\parsers\readers.py", line 1620, in __init__
    self._engine = self._make_engine(f, self.engine)
                   ^^^^^^^^^^^^^^^^^^^^^^^^^^^^^^^^^
  File "C:\Users\Asus-PC\AppData\Local\Programs\Python\Python311\Lib\site-packages\pandas\io\parsers\readers.py", line 1898, in _make_engine
    return mapping[engine](f, **self.options)
           ^^^^^^^^^^^^^^^^^^^^^^^^^^^^^^^^^^
  File "C:\Users\Asus-PC\AppData\Local\Programs\Python\Python311\Lib\site-packages\pandas\io\parsers\c_parser_wrapper.py", line 161, in __init__
    self._validate_parse_dates_presence(self.names)  # type: ignore[has-type]
    ^^^^^^^^^^^^^^^^^^^^^^^^^^^^^^^^^^^^^^^^^^^^^^^
  File "C:\Users\Asus-PC\AppData\Local\Programs\Python\Python311\Lib\site-packages\pandas\io\parsers\base_parser.py", line 243, in _validate_parse_dates_presence
    raise ValueError(
ValueError: Missing column provided to 'parse_dates': 'date'
2025-07-27 06:54:38 - INFO - __main__ - Initializing Streamlit dashboard
2025-07-27 06:54:38 - ERROR - utils - Failed to load aws_hybrid_usage.csv: ValueError
Error: Missing column provided to 'parse_dates': 'date'
File size: 3019 bytes
Traceback (most recent call last):
  File "C:\Users\Asus-PC\cloud-saver\streamlit\utils.py", line 42, in load_data
    df = pd.read_csv(
         ^^^^^^^^^^^^
  File "C:\Users\Asus-PC\AppData\Local\Programs\Python\Python311\Lib\site-packages\pandas\io\parsers\readers.py", line 1026, in read_csv
    return _read(filepath_or_buffer, kwds)
           ^^^^^^^^^^^^^^^^^^^^^^^^^^^^^^^
  File "C:\Users\Asus-PC\AppData\Local\Programs\Python\Python311\Lib\site-packages\pandas\io\parsers\readers.py", line 620, in _read
    parser = TextFileReader(filepath_or_buffer, **kwds)
             ^^^^^^^^^^^^^^^^^^^^^^^^^^^^^^^^^^^^^^^^^^
  File "C:\Users\Asus-PC\AppData\Local\Programs\Python\Python311\Lib\site-packages\pandas\io\parsers\readers.py", line 1620, in __init__
    self._engine = self._make_engine(f, self.engine)
                   ^^^^^^^^^^^^^^^^^^^^^^^^^^^^^^^^^
  File "C:\Users\Asus-PC\AppData\Local\Programs\Python\Python311\Lib\site-packages\pandas\io\parsers\readers.py", line 1898, in _make_engine
    return mapping[engine](f, **self.options)
           ^^^^^^^^^^^^^^^^^^^^^^^^^^^^^^^^^^
  File "C:\Users\Asus-PC\AppData\Local\Programs\Python\Python311\Lib\site-packages\pandas\io\parsers\c_parser_wrapper.py", line 161, in __init__
    self._validate_parse_dates_presence(self.names)  # type: ignore[has-type]
    ^^^^^^^^^^^^^^^^^^^^^^^^^^^^^^^^^^^^^^^^^^^^^^^
  File "C:\Users\Asus-PC\AppData\Local\Programs\Python\Python311\Lib\site-packages\pandas\io\parsers\base_parser.py", line 243, in _validate_parse_dates_presence
    raise ValueError(
ValueError: Missing column provided to 'parse_dates': 'date'
2025-07-27 06:54:38 - CRITICAL - __main__ - Critical dashboard error: Missing column provided to 'parse_dates': 'date'
Traceback (most recent call last):
  File "C:\Users\Asus-PC\cloud-saver\streamlit\app.py", line 80, in main
    cost_data = load_data(cost_data_path)
                ^^^^^^^^^^^^^^^^^^^^^^^^^
  File "C:\Users\Asus-PC\cloud-saver\streamlit\utils.py", line 42, in load_data
    df = pd.read_csv(
         ^^^^^^^^^^^^
  File "C:\Users\Asus-PC\AppData\Local\Programs\Python\Python311\Lib\site-packages\pandas\io\parsers\readers.py", line 1026, in read_csv
    return _read(filepath_or_buffer, kwds)
           ^^^^^^^^^^^^^^^^^^^^^^^^^^^^^^^
  File "C:\Users\Asus-PC\AppData\Local\Programs\Python\Python311\Lib\site-packages\pandas\io\parsers\readers.py", line 620, in _read
    parser = TextFileReader(filepath_or_buffer, **kwds)
             ^^^^^^^^^^^^^^^^^^^^^^^^^^^^^^^^^^^^^^^^^^
  File "C:\Users\Asus-PC\AppData\Local\Programs\Python\Python311\Lib\site-packages\pandas\io\parsers\readers.py", line 1620, in __init__
    self._engine = self._make_engine(f, self.engine)
                   ^^^^^^^^^^^^^^^^^^^^^^^^^^^^^^^^^
  File "C:\Users\Asus-PC\AppData\Local\Programs\Python\Python311\Lib\site-packages\pandas\io\parsers\readers.py", line 1898, in _make_engine
    return mapping[engine](f, **self.options)
           ^^^^^^^^^^^^^^^^^^^^^^^^^^^^^^^^^^
  File "C:\Users\Asus-PC\AppData\Local\Programs\Python\Python311\Lib\site-packages\pandas\io\parsers\c_parser_wrapper.py", line 161, in __init__
    self._validate_parse_dates_presence(self.names)  # type: ignore[has-type]
    ^^^^^^^^^^^^^^^^^^^^^^^^^^^^^^^^^^^^^^^^^^^^^^^
  File "C:\Users\Asus-PC\AppData\Local\Programs\Python\Python311\Lib\site-packages\pandas\io\parsers\base_parser.py", line 243, in _validate_parse_dates_presence
    raise ValueError(
ValueError: Missing column provided to 'parse_dates': 'date'
2025-07-27 06:58:03 - INFO - __main__ - Initializing Streamlit dashboard
2025-07-27 06:58:04 - INFO - utils - Successfully loaded 62 records from aws_hybrid_usage.csv
Columns: ['service', 'cost', 'usage', 'data_type', 'usage_start_time']
Date columns detected: ['usage_start_time']
Date range: 2025-07-22 00:00:00 to 2025-08-21 00:00:00
2025-07-27 06:58:04 - ERROR - utils - Failed to load aws_hybrid_spot_instances.csv: UnboundLocalError
Error: cannot access local variable 'primary_date_col' where it is not associated with a value
File size: 3478 bytes
Traceback (most recent call last):
  File "C:\Users\Asus-PC\cloud-saver\streamlit\utils.py", line 79, in load_data
    f"Date range: {df[primary_date_col].min()} to {df[primary_date_col].max() if 'primary_date_col' in locals() else 'N/A'}"
                      ^^^^^^^^^^^^^^^^
UnboundLocalError: cannot access local variable 'primary_date_col' where it is not associated with a value
2025-07-27 06:58:04 - CRITICAL - __main__ - Critical dashboard error: cannot access local variable 'primary_date_col' where it is not associated with a value
Traceback (most recent call last):
  File "C:\Users\Asus-PC\cloud-saver\streamlit\app.py", line 81, in main
    spot_data = load_data(spot_data_path)
                ^^^^^^^^^^^^^^^^^^^^^^^^^
  File "C:\Users\Asus-PC\cloud-saver\streamlit\utils.py", line 79, in load_data
    f"Date range: {df[primary_date_col].min()} to {df[primary_date_col].max() if 'primary_date_col' in locals() else 'N/A'}"
                      ^^^^^^^^^^^^^^^^
UnboundLocalError: cannot access local variable 'primary_date_col' where it is not associated with a value
2025-07-27 07:01:27 - INFO - __main__ - Initializing Streamlit dashboard
2025-07-27 07:01:27 - INFO - utils - Successfully loaded 62 records from aws_hybrid_usage.csv
Columns: ['service', 'cost', 'usage', 'data_type', 'usage_start_time']
Date columns detected: ['usage_start_time']
Date range: 2025-07-22 00:00:00 to 2025-08-21 00:00:00
2025-07-27 07:01:27 - INFO - utils - Successfully loaded 50 records from aws_hybrid_spot_instances.csv
Columns: ['instance_id', 'launch_time', 'duration_hours', 'interrupted', 'data_type']
Date columns detected: []
No date column available for range calculation
2025-07-27 07:01:27 - WARNING - utils - Negative costs detected in data
2025-07-27 07:01:27 - INFO - __main__ - Rendering cost analysis
2025-07-27 07:01:28 - INFO - __main__ - Cost analysis rendered successfully
2025-07-27 07:01:28 - INFO - __main__ - Rendering spot instance optimizer
2025-07-27 07:01:28 - INFO - cost_calculator - Initializing savings calculator
2025-07-27 07:01:28 - WARNING - utils - Negative costs detected in data
2025-07-27 07:01:28 - INFO - cost_calculator - Successfully calculated savings: $250.00/month at Medium level
